<?xml version="1.0"?>
<robot xmlns:xacro="http://www.ros.org/wiki/xacro" name="gz_example_robot">

<xacro:property name="imu_translation" value="0.0628 -0.0314 -0.0393" />
<xacro:property name="rockers_joint_type" value="revolute"/>

  <!-- Rocker Link MACRO -->
  <xacro:macro name="rocker_link" params="name">
    <link name="rocker_link">
      <inertial>
        <mass value="1.387336"/>
        <origin xyz="0 0.01346 -0.06506"/>
        <inertia
          ixx="0.002956" ixy="-0.000001489324" ixz="-0.000008103407"
          iyy="0.02924"  iyz="0.00007112"
          izz="0.02832"/>
      </inertial>
      <visual>
        <geometry>
          <mesh filename="package://leo_description/models/Rocker.dae"/>
        </geometry>
      </visual>
      <collision>
        <geometry>
          <mesh filename="package://leo_description/models/Rocker_outline.stl"/>
        </geometry>
      </collision>
    </link>
  </xacro:macro>

  <!-- Wheel Link MACRO-->
  <xacro:macro name="wheel_link" params="name model"> 
    <link name="wheel_link">
      <inertial>
        <mass value="0.283642"/>
        <origin xyz="0 0.030026 0"/>
        <inertia
          ixx="0.000391"  ixy="0.00000123962" ixz="5.52582e-7"
          iyy="0.0004716" iyz="-0.000002082042"
          izz="0.000391"/>
      </inertial>
      <visual>
        <geometry>
          <mesh filename="package://leo_description/models/Wheel${model}.dae"/>
        </geometry>
      </visual>
      <collision>
        <origin xyz="0 0.04485 0" rpy="${pi/2} 0 0"/>
        <geometry>
          <cylinder radius="0.057" length="0.07"/>
        </geometry>
      </collision>
      <collision>
        <origin xyz="0 0.04485 0" rpy="${pi/2} 0 0"/>
        <geometry>
          <cylinder radius="0.0625" length="0.04"/>
        </geometry>
      </collision>
      <collision>
        <geometry>
          <mesh filename="package://leo_description/models/Wheel_outline.stl"/>
        </geometry>
      </collision>
    </link>
  </xacro:macro>

  <!-- LINKS -->
  <!-- BASE FOOTPRINT -->
  <link name="base_footprint"/>

  <!-- BASE LINK -->
  <link name="base_link">
    <inertial>
      <mass value="1.584994"/>
      <origin xyz="-0.019662 0.011643 -0.031802"/>
      <inertia
        ixx="0.01042" ixy="0.001177" ixz="-0.0008871"
        iyy="0.01045" iyz="0.0002226"
        izz="0.01817"/>
    </inertial>
    <visual>
      <geometry>
        <mesh filename="package://leo_description/models/Chassis.dae"/>
      </geometry>
    </visual>
    <collision>
      <geometry>
        <mesh filename="package://leo_description/models/Chassis_outline.stl"/>
      </geometry>
    </collision>
  </link>

  <!-- ROCKERS AND WHEELS-->
  <xacro:rocker_link name="L"/>
  <xacro:rocker_link name="R"/>
  <xacro:wheel_link name="FL" model="A"/>
  <xacro:wheel_link name="RL" model="A"/>
  <xacro:wheel_link name="FR" model="B"/>
  <xacro:wheel_link name="RR" model="B"/>
    
  <!-- ANTENNA -->
    <link name="antenna_link">
      <inertial>
        <mass value="0.001237"/>
        <origin xyz="0 0 0.028828"/>
        <inertia
          ixx="2.5529e-7" ixy="0.0" ixz="0.0"
          iyy="2.5529e-7" iyz="0.0"
          izz="1.354e-8"/>
      </inertial>
      <visual>
        <geometry>
          <mesh filename="package://leo_description/models/Antenna.dae"/>
        </geometry>
      </visual>
      <collision>
        <origin xyz="0 0 0.028"/>
        <geometry>
          <cylinder radius="0.0055" length="0.056"/>
        </geometry>
      </collision>
    </link>

  <!-- LiDAR..................................................................................................................... -->
  <!-- <link name="lidar_link">
    <visual>
      <origin xyz="0 0 0.03"/>
      <geometry>
        <box size="0.079 0.086 0.006"/>
      </geometry>
      <material name="support">
        <color rgba="0.5 0.5 0.5 1.0"/>
      </material>
    </visual>
    <visual>
      <origin xyz="0 0 0.023"/>
      <geometry>
        <cylinder radius="0.038" length="0.04"/>
      </geometry>
      <material name="lidar">
        <color rgba="1.0 0.0 0.0 0.7"/>
      </material>
    </visual>
    <collision>
      <origin xyz="0 0 0.003"/>
      <geometry>
        <box size="0.079 0.086 0.006"/>
      </geometry>
    </collision>
    <collision>
      <origin xyz="0 0 0.023"/>
      <geometry>
        <cylinder radius="0.038" length="0.04"/>
      </geometry>
    </collision>
  </link> -->

    <link name="lidar_link">
    <visual>
      <geometry>
        <cylinder length="0.03" radius="0.04" />
      </geometry>
      <origin rpy="0 0 0" xyz="0 0 0.03"/>
      <material name="black">
        <color rgba="0.1 0.1 0.1 1"/>
      </material>
    </visual>

    <collision>
      <geometry>
        <cylinder length="0.03" radius="0.03" />
      </geometry>
      <origin rpy="0 0 0" xyz="0 0 0.03"/>
    </collision>

    <inertial>
      <mass value="0.1"/>
      <inertia ixx="0.0005" ixy="0.0" ixz="0.0" iyy="0.0005" iyz="0.0" izz="0.00045"/>
    </inertial>
  </link>

  <!-- TBD............................................................................................................... -->
  <link name="camera_frame"/>
  <link name="camera_optical_frame"/>
  <link name="imu_frame"/>
  <!-- <link name="laser_frame"/> -->


  <!-- JOINTS -->

  <joint name="base_footprint_joint" type="fixed">
    <origin xyz="0 0 0.19783" rpy="0 0 0"/>
    <parent link="base_footprint"/>
    <child link="base_link"/>
  </joint>

  <joint name="rocker_L_joint" type="${rockers_joint_type}">
    <origin xyz="0.00263 0.14167 -0.04731" rpy="0 0 ${pi}"/>
    <parent link="base_link"/>
    <child link="rocker_L_link"/>
    <axis xyz="0 1 0"/>
    <limit effort="100.0" lower="-0.24" upper="0.24" velocity="100.0"/>
    <dynamics friction="1.0" damping="0.1"/>
  </joint>

  <joint name="rocker_R_joint" type="${rockers_joint_type}">
    <origin xyz="0.00263 -0.14167 -0.04731" rpy="0 0 0"/>
    <parent link="base_link"/>
    <child link="rocker_R_link"/>
    <axis xyz="0 1 0"/>
    <limit effort="100.0" lower="-0.24" upper="0.24" velocity="100.0"/>
    <dynamics friction="1.0" damping="0.1"/> 
    <mimic joint="rocker_L_joint"/>
  </joint>

  <joint name="wheel_FL_joint" type="continuous">
    <origin xyz="-0.15256 -0.08214 -0.08802" rpy="0 0 0"/>
    <parent link="rocker_L_link"/>
    <child link="wheel_FL_link"/>
    <axis xyz="0 -1 0"/>
    <limit effort="2.0" velocity="6.0"/>
    <dynamics friction="0.3125" damping="0.1"/>
  </joint>

  <joint name="wheel_RL_joint" type="continuous">
    <origin xyz="0.15256 -0.08214 -0.08802" rpy="0 0 0"/>
    <parent link="rocker_L_link"/>
    <child link="wheel_RL_link"/>
    <axis xyz="0 -1 0"/>
    <limit effort="2.0" velocity="6.0"/>
    <dynamics friction="0.3125" damping="0.1"/>
  </joint>

  <joint name="wheel_FR_joint" type="continuous">
    <origin xyz="0.15256 -0.08214 -0.08802" rpy="0 0 0"/>
    <parent link="rocker_R_link"/>
    <child link="wheel_FR_link"/>
    <axis xyz="0 1 0"/>
    <limit effort="2.0" velocity="6.0"/>
    <dynamics friction="0.3125" damping="0.1"/>
  </joint>

  <joint name="wheel_RR_joint" type="continuous">
    <origin xyz="-0.15256 -0.08214 -0.08802" rpy="0 0 0"/>
    <parent link="rocker_R_link"/>
    <child link="wheel_RR_link"/>
    <axis xyz="0 1 0"/>
    <limit effort="2.0" velocity="6.0"/>
    <dynamics friction="0.3125" damping="0.1"/> 
  </joint>

    <joint name="antenna_joint" type="fixed">
      <origin xyz="-0.0052 0.056 -0.0065" rpy="0 0 0"/>
      <parent link="base_link"/>
      <child link="antenna_link"/>
    </joint>

  <joint name="camera_joint" type="fixed">
    <origin xyz="0.0971 0 -0.0427" rpy="0 0.2094 0"/>
    <parent link="base_link"/>
    <child link="camera_frame"/>
  </joint>

  <joint name="camera_optical_joint" type="fixed">
    <origin xyz="0 0 0" rpy="-${pi/2} 0.0 -${pi/2}"/>
    <parent link="camera_frame"/>
    <child link="camera_optical_frame"/>
  </joint>

  <joint name="imu_joint" type="fixed">
    <origin xyz="${imu_translation}" rpy="0 0 0"/>
    <parent link="base_link"/>
    <child link="imu_frame"/>
  </joint>

  <joint name="lidar_joint" type="fixed">
    <origin xyz="0.1 0 0.0" rpy="0 0 0"/>
    <parent link="base_link"/>
    <child link="lidar_link"/>
  </joint>

<!-- 
  <joint name="laser_joint" type="fixed">
    <origin xyz="0 0 0.0368" rpy="0 0 ${pi}"/>
    <parent link="laser_frame"/>
    <child link="lidar_link"/>
  </joint> -->

<!-- LEO GAZEBO -->

  <gazebo>
    <plugin
      filename="libignition-gazebo-diff-drive-system.so" name="ignition::gazebo::systems::DiffDrive">
      <tf_topic>/model/gz_example_robot/tf</tf_topic>

      <!-- TF Frames -->
      <frame_id>odom</frame_id>
      <child_frame_id>base_footprint</child_frame_id>
      <!-- Wheel Joints -->
      <left_joint>wheel_FL_joint</left_joint>
      <right_joint>wheel_FR_joint</right_joint>
      <left_joint>wheel_RL_joint</left_joint>
      <right_joint>wheel_RR_joint</right_joint>
      <wheel_separation>0.358</wheel_separation>
      <wheel_radius>0.0625</wheel_radius>

      <odom_publish_frequency>50</odom_publish_frequency>

      <!-- Topics -->
      <topic>/model/gz_example_robot/cmd_vel</topic>
      <odom_topic>/model/gz_example_robot/odometry</odom_topic>
      
      <max_linear_acceleration>2.5</max_linear_acceleration>
      <max_angular_acceleration>3</max_angular_acceleration>
      <min_linear_acceleration>-2.5</min_linear_acceleration>
      <min_angular_acceleration>-3</min_angular_acceleration>
    </plugin>
  </gazebo>

  <gazebo>
    <plugin filename="ignition-gazebo-joint-state-publisher-system" name="ignition::gazebo::systems::JointStatePublisher">
      <update_rate>50</update_rate>
      <topic>/world/empty/model/gz_example_robot/joint_state</topic>
    </plugin>
  </gazebo>


  <!-- base ODE properties -->
  <gazebo reference="base_footprint">
    <collision>
      <surface>
        <friction>
          <ode>
            <mu>0.3</mu>
            <mu2>0.3</mu2>
          </ode>
          <bullet>
            <friction>0.3</friction>
            <friction2>0.3</friction2>
            <rolling_friction>0.1</rolling_friction>
          </bullet>
        </friction>
      </surface>
    </collision>
  </gazebo>

  <gazebo reference="base_link">
    <collision>
      <surface>
        <friction>
          <ode>
            <mu>0.3</mu>
            <mu2>0.3</mu2>
          </ode>
          <bullet>
            <friction>0.3</friction>
            <friction2>0.3</friction2>
            <rolling_friction>0.1</rolling_friction>
          </bullet>
        </friction>
      </surface>
    </collision>
  </gazebo>

  <!-- rocker ODE properties -->
  <gazebo reference="rocker_L_link">
    <collision>
      <surface>
        <friction>
          <ode>
            <mu>0.3</mu>
            <mu2>0.3</mu2>
          </ode>
          <bullet>
            <friction>0.3</friction>
            <friction2>0.3</friction2>
            <rolling_friction>0.1</rolling_friction>
          </bullet>
        </friction>
      </surface>
    </collision>
  </gazebo>

  <gazebo reference="rocker_R_link">
    <collision>
      <surface>
        <friction>
          <ode>
            <mu>0.3</mu>
            <mu2>0.3</mu2>
          </ode>
          <bullet>
            <friction>0.3</friction>
            <friction2>0.3</friction2>
            <rolling_friction>0.1</rolling_friction>
          </bullet>
        </friction>
      </surface>
    </collision>
  </gazebo>

  <!-- wheel ODE properties -->
  <gazebo reference="wheel_FL_link">
    <collision>
      <surface>
        <friction>
          <ode>
            <mu>1</mu>
            <mu2>1</mu2>
            <slip1>0.035</slip1>
            <slip2>0</slip2>
            <fdir1>0 0 1</fdir1>
          </ode>
          <bullet>
            <friction>1</friction>
            <friction2>1</friction2>
            <rolling_friction>0.1</rolling_friction>
          </bullet>
        </friction>
      </surface>
    </collision>
  </gazebo>

  <gazebo reference="wheel_FR_link">
    <collision>
      <surface>
        <friction>
          <ode>
            <mu>1</mu>
            <mu2>1</mu2>
            <slip1>0.035</slip1>
            <slip2>0</slip2>
            <fdir1>0 0 1</fdir1>
          </ode>
          <bullet>
            <friction>1</friction>
            <friction2>1</friction2>
            <rolling_friction>0.1</rolling_friction>
          </bullet>
        </friction>
      </surface>
    </collision>
  </gazebo>

  <gazebo reference="wheel_RL_link">
    <collision>
      <surface>
        <friction>
          <ode>
            <mu>1</mu>
            <mu2>1</mu2>
            <slip1>0.035</slip1>
            <slip2>0</slip2>
            <fdir1>0 0 1</fdir1>
          </ode>
          <bullet>
            <friction>1</friction>
            <friction2>1</friction2>
            <rolling_friction>0.1</rolling_friction>
          </bullet>
        </friction>
      </surface>
    </collision>
  </gazebo>

  <gazebo reference="wheel_RR_link">
    <collision>
      <surface>
        <friction>
          <ode>
            <mu>1</mu>
            <mu2>1</mu2>
            <slip1>0.035</slip1>
            <slip2>0</slip2>
            <fdir1>0 0 1</fdir1>
          </ode>
          <bullet>
            <friction>1</friction>
            <friction2>1</friction2>
            <rolling_friction>0.1</rolling_friction>
          </bullet>
        </friction>
      </surface>
    </collision>
  </gazebo>

  <!-- camera -->
  <gazebo reference="camera_frame">
    <sensor name="camera" type="camera">
        <camera name="leo_camera">
            <horizontal_fov>1.9</horizontal_fov>
            <image>
                <width>640</width>
                <height>480</height>
                <format>R8G8B8</format>
            </image>
            <clip>
                <near>0.2</near>
                <far>300</far>
            </clip>
            <noise>
              <type>gaussian</type>
              <mean>0.0</mean>
              <stddev>0.007</stddev>
            </noise>
            <distortion>
              <k1>-0.279817</k1>
              <k2>0.060321</k2>
              <k3>0.000487</k3>
              <p1>0.000310</p1>
              <p2>0.000000</p2>
              <center>0.5 0.5</center>
            </distortion>              
        </camera>
        <always_on>1</always_on>
        <update_rate>30</update_rate>
        <visualize>true</visualize>
        <topic>/camera/image_raw</topic>
        <ignition_frame_id>camera_frame</ignition_frame_id>
    </sensor>
  </gazebo>

  <!-- Gazebo configuration for LiDAR......................................................................................... -->

  <gazebo reference="lidar_link">
    <sensor type="gpu_lidar" name="generic_lidar_sensor">

      <topic>/model/gz_example_robot/scan</topic>
      <frame_id>lidar_link</frame_id>
      <ignition_frame_id>lidar_link</ignition_frame_id>

      <update_rate>10.0</update_rate>
      <ray>
        <scan>
          <horizontal>
            <samples>512</samples>
            <resolution>1</resolution>
            <min_angle>-${pi*0.75}</min_angle>
            <max_angle>${pi*0.75}</max_angle>
          </horizontal>
        </scan>
        <range>
          <min>0.10</min>
          <max>10.0</max>
          <resolution>0.03</resolution>
        </range>
        <noise>
          <type>gaussian</type>
          <mean>0.0</mean>
          <stddev>0.001</stddev>
        </noise>
      </ray>
      <always_on>1</always_on>
      <visualize>false</visualize>
    </sensor>
  </gazebo>
  <gazebo>
    <plugin filename="libignition-gazebo-sensors-system.so" name="ignition::gazebo::systems::Sensors">
      <render_engine>ogre2</render_engine>
    </plugin>
  </gazebo>

    <!-- rocker differential
    <gazebo>
      <plugin 
        filename="libleo_gz_differential_plugin.so"

        name="leo_gz::DifferentialSystem" >
        <jointA>rocker_L_joint</jointA>
        <jointB>rocker_R_joint</jointB>
        <forceConstant>100.0</forceConstant>
      </plugin>
    </gazebo> -->

  <gazebo reference="imu_frame">
    <sensor type="imu" name="leo_imu_sensor">
      <always_on>true</always_on>
      <update_rate>100</update_rate>
      <visualize>true</visualize>
      <topic>/model/gz_example_robot/imu</topic>
      <frame_id>imu_frame</frame_id>
      <ignition_frame_id>imu_frame</ignition_frame_id>
      <plugin filename="libignition-gazebo-imu-system.so" name="ignition::gazebo::systems::Imu">
        <initial_orientation_as_reference>false</initial_orientation_as_reference>
      </plugin>
    </sensor>
  </gazebo>

</robot>